Workbook

Sheet ANLEITUNG
B2: Anleitung für den Abitur-Planer
B4: Mithilfe von diesem Abitur-Planer soll die Kurswahl und die Notenberechnung für das Abitur einfacher und transparenter gestaltet sein.
B5: Alle Regeln der Gesetzestexte sind hier übernommen, sodass die Kurswahl und Notenberechnung exemplarisch und korrekt durchgeführt werden kann.
B6: → VO-GO Berlin
B8: Speichert euch bitte zunächst oben rechts eine Kopie (auf das grüne Pop-Up klicken), sonst könnt ihr die Datei nicht bearbeiten!
B10: Es gibt 2 für euch wichtige Sheets
B11: Kurswahl | C11: Hier könnt ihr eure Kurse für die Oberstufe wählen. Links sind die Kurse zu finden und rechts findet ihr die Regeln. Klickt bitte auf die jeweiligen Kästchen, um die Kurse auszuwählen. Einige Kurse könnt ihr z. B. für Q3/Q4 nicht auswählen, da die nicht für beide Abiturjahre am HCG angeboten werden. Die Prüfungsfächer wählt ihr in der grauen Spalte „PF“ aus. Am Ende müssen alle Regeln WAHR sein!
B13: Notenrechner | C13: Mit eurer Kurswahl könnt ihr hier jetzt eure Abitur-Note ausrechnen. Dafür tragt ihr links vom Kästchen eure Noten ein und hakt einfach alle Kurse ab, die ihr einbringen wollt. Nur die abgehakten Kurse bzw. Noten zählen dann in die Abi-Note ein. Ihr müsst genau 32 Kurse auswählen (1. Regel), damit eure Note vollständig gültig ist! Bei weniger als 32 Kursen ist das eure angepeilte Note. Insgesamt müssen alle Regeln rechts WAHR sein, damit die Note auch so gültig ist!
B15: Belegen heißt, ihr besucht die Kurse im Abitur, einbringen heißt die Kurse zählen auch wirklich in eure Abitur-Note. Nicht jeder Kurs muss in eure Note zählen, aber einige schon. Und dafür gibt es Regeln.
B17: Ihr könnt gerne den Notenrechner mit Vermutungen auffüllen, um euch auszurechnen, welche Note ihr im Abi bekommen könntet. Füllt dafür am Besten erst alles aus und guckt erst dann, welche Regeln falsch sind.
B18: Am besten, ihr benutzt den Notenrechner am Computer oder Laptop.
B19: Viel Spaß!
B21: Nachfragen bitte an schuelervertretung@hcog.de
B23: Dieser Abitur-Rechner basiert auf der Fassung der VO-GO Berlin vom 01.11.2025
B24: Für die Richtigkeit der Berechnungen und Ergebnisse wird keine Haftung übernommen
B25: © Johann Stein, 2026

Sheet Angebotene Kurse
B2: Angebotene Kurse
C3: Kurs | D3: LK? | E3: Q1/2 | F3: Q3/4 | G3: Typ
B4: 1. Aufgabenfeld | C4: Deutsch | D4: TRUE | E4: TRUE | F4: TRUE
C5: Englisch | D5: TRUE | E5: TRUE | F5: TRUE | G5: Fremdsprache
C6: Französisch | D6: TRUE | E6: TRUE | F6: TRUE | G6: Fremdsprache
C7: Spanisch | D7: FALSE | E7: TRUE | F7: TRUE | G7: Fremdsprache
C8: Latein | D8: FALSE | E8: TRUE | F8: TRUE | G8: Fremdsprache
C9: Musik | D9: TRUE | E9: TRUE | F9: TRUE | G9: Künstlerisch
C10: Kunst | D10: TRUE | E10: TRUE | F10: TRUE | G10: Künstlerisch
C11: DS | D11: FALSE | E11: TRUE | F11: TRUE | G11: Künstlerisch
B12: 2. Aufgabenfeld | C12: Geschichte | D12: TRUE | E12: TRUE | F12: TRUE | G12: Gesellschaftswissenschaft
C13: Geschichte bili | D13: FALSE | E13: TRUE | F13: TRUE | G13: Gesellschaftswissenschaft
C14: Politikwissenschaften | D14: TRUE | E14: TRUE | F14: TRUE | G14: Gesellschaftswissenschaft
C15: Geografie | D15: TRUE | E15: TRUE | F15: TRUE | G15: Gesellschaftswissenschaft
C16: Geografie bili | D16: FALSE | E16: TRUE | F16: TRUE | G16: Gesellschaftswissenschaft
C17: Philosophie | D17: FALSE | E17: TRUE | F17: TRUE | G17: Gesellschaftswissenschaft
B18: 3. Aufgabenfeld | C18: Mathematik | D18: TRUE | E18: TRUE | F18: TRUE
C19: Physik | D19: TRUE | E19: TRUE | F19: TRUE | G19: Naturwissenschaft
C20: Chemie | D20: TRUE | E20: TRUE | F20: TRUE | G20: Naturwissenschaft
C21: Biologie | D21: TRUE | E21: TRUE | F21: TRUE | G21: Naturwissenschaft
C22: Informatik | D22: FALSE | E22: TRUE | F22: TRUE
B23: Sport | C23: Sport | D23: FALSE | E23: TRUE | F23: TRUE
C24: Sport Theorie | D24: FALSE | E24: FALSE | F24: TRUE
C25: Skifahrt | D25: FALSE | E25: TRUE | F25: FALSE
B26: Zusatzkurse | C26: Chor | D26: FALSE | E26: TRUE | F26: TRUE | G26: Ensemblemusik
C27: Orchester | D27: FALSE | E27: TRUE | F27: TRUE | G27: Ensemblemusik
C28: Digitale Welten | D28: FALSE | E28: TRUE | F28: FALSE | G28: Informatik
C29: Neuro | D29: FALSE | E29: TRUE | F29: FALSE | G29: Philosophie
C30: STUB (ESB) | D30: FALSE | E30: TRUE | F30: FALSE | G30: Beruf & Studium
C31: Sportmedizin | D31: FALSE | E31: TRUE | F31: FALSE | G31: Biologie
C32: CCC | D32: FALSE | E32: TRUE | F32: TRUE | G32: Englisch
C33: Debating | D33: FALSE | E33: TRUE | F33: TRUE | G33: Englisch
B35: Kommentare ⇒

Sheet Kurswahl
B2: Kurswahl | J2: Zu erfüllende Regeln
C3: Kurs | D3: PF | E3: Q1/2 | F3: Q3/4 | G3: Ges.
B4: {=_xlfn.LET(_xlpm.bereich,'Angebotene Kurse'!$B$4:$C$33, IF(_xlpm.bereich="","",_xlpm.bereich))} -> 1. Aufgabenfeld | C4: Deutsch | E4: TRUE | F4: TRUE | G4: =IF((F4+E4)*2>0,(F4+E4)*2,"") -> 4 | J4: Zwei Leistungskurse 8 Semester und mind. 32 Semester Grundkurse | K4: {=_xlfn.LET( _xlpm.kopf,$B$3:$G$3, _xlpm.daten,$B$4:$G$40, _xlpm.spPF, INDEX(_xlpm.daten,0,MATCH("PF",_xlpm.kopf,0)), _xlpm.semester12_kopf, INDEX(_xlpm.daten,0,MATCH("Q1/2",_xlpm.kopf,0)), _xlpm.semester34_kopf, INDEX(_xlpm.daten,0,MATCH("Q3/4",_xlpm.kopf,0)), _xlpm.spKurs, INDEX(_xlpm.daten,0,MATCH("Kurs",_xlpm.kopf,0)), _xlpm.semester12, --(_xlpm.semester12_kopf=TRUE), _xlpm.semester34, --(_xlpm.semester34_kopf=TRUE), _xlpm.istLK, --(_xlpm.spPF="LF"), _xlpm.istGK, --(_xlpm.spPF<>"LF") * --(_xlpm.spKurs<>""), _xlpm.sk, --(_xlpm.spKurs="Skifahrt"), _xlpm.LF_durch, SUMPRODUCT(_xlpm.istLK * _xlpm.semester12 * _xlpm.semester34), _xlpm.LF_ok, _xlpm.LF_durch=2, _xlpm.sem_pro_zeile, _xlpm.sk*(_xlpm.semester12+_xlpm.semester34) + (1-_xlpm.sk)*2*(_xlpm.semester12+_xlpm.semester34), _xlpm.GK_sem, SUMPRODUCT(_xlpm.istGK * _xlpm.sem_pro_zeile), _xlfn.CONCAT(AND(_xlpm.LF_ok, _xlpm.GK_sem>=32)," (", _xlpm.GK_sem, ")") )} -> FALSCH (13)
C5: Englisch | E5: FALSE | F5: FALSE | G5: =IF((F5+E5)*2>0,(F5+E5)*2,"") | J5: Minimal 8, Maximal 12 Kurse pro Semester | K5: {=_xlfn.LET(_xlpm.semester12,INDEX(B3:G40,MATCH("ALLE",B3:B40,1),4),_xlpm.semester34,INDEX(B3:G40,MATCH("ALLE",B3:B40,1),5),IF(OR(_xlpm.semester12>12, _xlpm.semester34<8, _xlpm.semester12>12, _xlpm.semester34<8), FALSE, TRUE))} -> FALSE
C6: Französisch | E6: FALSE | F6: FALSE | G6: =IF((F6+E6)*2>0,(F6+E6)*2,"") | J6: Prüfungsfächer
C7: Spanisch | E7: FALSE | F7: FALSE | G7: =IF((F7+E7)*2>0,(F7+E7)*2,"") | J7: Alle Prüfungsfächer genau eingetragen (2x LF, 3. PF*, 4. PF*, 5. PK) | K7: {=_xlfn.LET( _xlpm.PFSp, INDEX($B$4:$G$40,0,MATCH("PF",$B$3:$G$3,0)), _xlpm.NormPF_raw, CLEAN(TRIM(_xlpm.PFSp)), _xlpm.NormPF, SUBSTITUTE(_xlpm.NormPF_raw,CHAR(160),""), _xlpm.cnteins, SUMPRODUCT(--(LEFT(_xlpm.NormPF,2)="LF")), _xlpm.cntzwei, SUMPRODUCT(--(LEFT(_xlpm.NormPF,5)="3. PF")), _xlpm.cntdrei, SUMPRODUCT(--(LEFT(_xlpm.NormPF,5)="4. PF")), _xlpm.cntvier, SUMPRODUCT(--(LEFT(_xlpm.NormPF,5)="5. PK")), AND(_xlpm.cnteins=2, _xlpm.cntzwei=1, _xlpm.cntdrei=1, _xlpm.cntvier=1) )} -> FALSE
C8: Latein | E8: FALSE | F8: FALSE | G8: =IF((F8+E8)*2>0,(F8+E8)*2,"") | J8: Ein Leistungskurs muss eine Fremdsprache*, Deutsch, Mathe oder eine NaWi sein | K8: {=_xlfn.LET( _xlpm.kopfzeilen,$B$3:$G$3, _xlpm.datenbereich,$B$4:$G$40, _xlpm.spalte_kurs,INDEX(_xlpm.datenbereich,0,MATCH("Kurs",_xlpm.kopfzeilen,0)), _xlpm.spalte_pf,INDEX(_xlpm.datenbereich,0,MATCH("PF",_xlpm.kopfzeilen,0)), _xlpm.angebot_kopf,'Angebotene Kurse'!$B$3:$G$3, _xlpm.angebot_daten,'Angebotene Kurse'!$B$4:$G$1002, _xlpm.fremdsprache_liste,_xlfn._xlws.FILTER(INDEX(_xlpm.angebot_daten,0,MATCH("Kurs",_xlpm.angebot_kopf,0)), INDEX(_xlpm.angebot_daten,0,MATCH("Typ",_xlpm.angebot_kopf,0))="Fremdsprache"), _xlpm.naturwissenschaft_liste,_xlfn._xlws.FILTER(INDEX(_xlpm.angebot_daten,0,MATCH("Kurs",_xlpm.angebot_kopf,0)), INDEX(_xlpm.angebot_daten,0,MATCH("Typ",_xlpm.angebot_kopf,0))="Naturwissenschaft"), _xlpm.ist_erlaubtes_fach,(_xlpm.spalte_kurs="Deutsch")+(_xlpm.spalte_kurs="Mathematik")+ISNUMBER(MATCH(_xlpm.spalte_kurs,_xlpm.fremdsprache_liste,0))+ISNUMBER(MATCH(_xlpm.spalte_kurs,_xlpm.naturwissenschaft_liste,0))>0, SUMPRODUCT((_xlpm.spalte_pf="LF")*_xlpm.ist_erlaubtes_fach)>=1 )} -> FALSE
C9: Musik | E9: FALSE | F9: FALSE | G9: =IF((F9+E9)*2>0,(F9+E9)*2,"") | J9: Zwei Kurse von Mathe, Deutsch und Fremdsprache müssen PFs sein (LF, 3. PF, 4. PF) | K9: {=_xlfn.LET( _xlpm.KursSp, INDEX($B$4:$G$40,0,MATCH("Kurs",$B$3:$G$3,0)), _xlpm.PFSp, INDEX($B$4:$G$40,0,MATCH("PF",$B$3:$G$3,0)), _xlpm.Kurs_FS, _xlfn._xlws.FILTER( INDEX('Angebotene Kurse'!$B$4:$G$29,0,MATCH("Kurs",'Angebotene Kurse'!$B$3:$G$3,0)), INDEX('Angebotene Kurse'!$B$4:$G$29,0,MATCH("Typ",'Angebotene Kurse'!$B$3:$G$3,0))="Fremdsprache" ), _xlpm.istPF, (_xlpm.PFSp="LF")+(_xlpm.PFSp="3. PF")+(_xlpm.PFSp="4. PF")>0, _xlpm.istZiel, (_xlpm.KursSp="Mathematik")+(_xlpm.KursSp="Deutsch")+ISNUMBER(MATCH(_xlpm.KursSp,_xlpm.Kurs_FS,0))>0, SUMPRODUCT(_xlpm.istPF*_xlpm.istZiel)>=2 )} -> FALSE
C10: Kunst | E10: FALSE | F10: FALSE | G10: =IF((F10+E10)*2>0,(F10+E10)*2,"") | J10: Prüfungsfächer 3 und 4 darf nur eines der Fächer Musik, Kunst, DS und Sport sein | K10: {=_xlfn.LET( _xlpm.kopfzeilen,$B$3:$G$3, _xlpm.datenbereich,$B$4:$G$40, _xlpm.spalte_kurs,INDEX(_xlpm.datenbereich,0,MATCH("Kurs",_xlpm.kopfzeilen,0)), _xlpm.spalte_pf,INDEX(_xlpm.datenbereich,0,MATCH("PF",_xlpm.kopfzeilen,0)), _xlpm.ist_kunstmusikdsport,(_xlpm.spalte_kurs="Musik")+(_xlpm.spalte_kurs="Kunst")+(_xlpm.spalte_kurs="DS")+(_xlpm.spalte_kurs="Sport")>0, _xlpm.anzahl_in_3_oder_4,SUMPRODUCT(((_xlpm.spalte_pf="3. PF")+(_xlpm.spalte_pf="4. PF")>0)*_xlpm.ist_kunstmusikdsport), _xlpm.anzahl_in_3_oder_4<=1 )} -> TRUE
C11: DS | E11: FALSE | F11: FALSE | G11: =IF((F11+E11)*2>0,(F11+E11)*2,"") | J11: Sport und DS dürfen nicht 3. PF sein | K11: {=_xlfn.LET( _xlpm.kopfzeilen,$B$3:$G$3, _xlpm.datenbereich,$B$4:$G$34, _xlpm.KursSp,INDEX(_xlpm.datenbereich,0,MATCH("Kurs",_xlpm.kopfzeilen,0)), _xlpm.PFSp,INDEX(_xlpm.datenbereich,0,MATCH("PF",_xlpm.kopfzeilen,0)), _xlpm.istSportOderDS,((_xlpm.KursSp="Sport")+(_xlpm.KursSp="DS"))>0, _xlpm.anzahlVerboten,SUMPRODUCT(--_xlpm.istSportOderDS*--(_xlpm.PFSp="3. PF")), _xlpm.anzahlVerboten=0 )} -> TRUE
B12: 2. Aufgabenfeld | C12: Geschichte | E12: FALSE | F12: FALSE | G12: =IF((F12+E12)*2>0,(F12+E12)*2,"") | J12: Prüfungsfächer + 5. PK aus allen 3 Aufgabenfeldern | K12: {=_xlfn.LET( _xlpm.PFSp, INDEX($B$4:$G$40,0,MATCH("PF",$B$3:$G$3,0)), _xlpm.Z, ROW($B$4:$B$40), _xlpm.aufgabenfeld1, _xlfn.AGGREGATE(15,6,_xlpm.Z/($B$4:$B$40="1. Aufgabenfeld"),1), _xlpm.aufgabenfeld2, _xlfn.AGGREGATE(15,6,_xlpm.Z/($B$4:$B$40="2. Aufgabenfeld"),1), _xlpm.aufgabenfeld3, _xlfn.AGGREGATE(15,6,_xlpm.Z/($B$4:$B$40="3. Aufgabenfeld"),1), _xlpm.istRelev, (_xlpm.PFSp="LF")+(_xlpm.PFSp="3. PF")+(_xlpm.PFSp="4. PF")+(_xlpm.PFSp="5. PK")>0, _xlpm.inFeld1, (_xlpm.Z>=_xlpm.aufgabenfeld1)*(_xlpm.Z<_xlpm.aufgabenfeld2), _xlpm.inFeld2, (_xlpm.Z>=_xlpm.aufgabenfeld2)*(_xlpm.Z<_xlpm.aufgabenfeld3), _xlpm.inFeld3, (_xlpm.Z>=_xlpm.aufgabenfeld3), _xlpm.hateins, SUMPRODUCT(_xlpm.istRelev*_xlpm.inFeld1)>0, _xlpm.hatzwei, SUMPRODUCT(_xlpm.istRelev*_xlpm.inFeld2)>0, _xlpm.hatdrei, SUMPRODUCT(_xlpm.istRelev*_xlpm.inFeld3)>0, AND(_xlpm.hateins,_xlpm.hatzwei,_xlpm.hatdrei) )} -> FALSE
C13: Geschichte bili | E13: FALSE | F13: FALSE | G13: =IF((F13+E13)*2>0,(F13+E13)*2,"") | J13: Ist Sport PF oder 5. PK: Zwei Semester Sport Theorie belegen | K13: {=_xlfn.LET( _xlpm.kopfzeilen,$B$3:$G$3, _xlpm.datenbereich,$B$4:$G$40, _xlpm.spalte_kurs,INDEX(_xlpm.datenbereich,0,MATCH("Kurs",_xlpm.kopfzeilen,0)), _xlpm.spalte_pf,INDEX(_xlpm.datenbereich,0,MATCH("PF",_xlpm.kopfzeilen,0)), _xlpm.spalte_q12,INDEX(_xlpm.datenbereich,0,MATCH("Q1/2",_xlpm.kopfzeilen,0)), _xlpm.spalte_q34,INDEX(_xlpm.datenbereich,0,MATCH("Q3/4",_xlpm.kopfzeilen,0)), _xlpm.sport_ist_pf_oder_pk5,SUMPRODUCT((((_xlpm.spalte_pf="LF")+(_xlpm.spalte_pf="3. PF")+(_xlpm.spalte_pf="4. PF")+(_xlpm.spalte_pf="5. PK"))>0)*(((_xlpm.spalte_kurs="Sport")+(_xlpm.spalte_kurs="Sport Theorie"))>0))>0, _xlpm.sport_theorie_hat_mind2,SUMPRODUCT((_xlpm.spalte_kurs="Sport Theorie")*(((_xlpm.spalte_q12=TRUE)+(_xlpm.spalte_q34=TRUE))>=1))>0, IF(_xlpm.sport_ist_pf_oder_pk5, _xlpm.sport_theorie_hat_mind2, TRUE) )} -> TRUE
C14: Politikwissenschaften | E14: FALSE | F14: FALSE | G14: =IF((F14+E14)*2>0,(F14+E14)*2,"") | J14: Zusatzkurse/Ski/Sport Theorie sind keine Prüfungsfächer/Referenzfach der 5. PK | K14: {=_xlfn.LET( _xlpm.kopfzeilen,$B$3:$G$3, _xlpm.datenbereich,$B$4:$G$40, _xlpm.spalte_kurs,INDEX(_xlpm.datenbereich,0,MATCH("Kurs",_xlpm.kopfzeilen,0)), _xlpm.spalte_pf,INDEX(_xlpm.datenbereich,0,MATCH("PF",_xlpm.kopfzeilen,0)), _xlpm.zeilenindex,ROW($B$4:$B$40), _xlpm.start_zusatz,_xlfn.AGGREGATE(15,6,_xlpm.zeilenindex/($B$4:$B$40="Zusatzkurse"),1), _xlpm.in_zusatzbereich,(_xlpm.zeilenindex>=_xlpm.start_zusatz), _xlpm.ist_pf_markiert,(_xlpm.spalte_pf="LF")+(_xlpm.spalte_pf="3. PF")+(_xlpm.spalte_pf="4. PF")+(_xlpm.spalte_pf="5. PK")>0, _xlpm.ist_ski_oder_theorie,(_xlpm.spalte_kurs="Skifahrt")+(_xlpm.spalte_kurs="Sport Theorie")>0, SUMPRODUCT((_xlpm.in_zusatzbereich+_xlpm.ist_ski_oder_theorie>0)*_xlpm.ist_pf_markiert)=0 )} -> TRUE
C15: Geografie | E15: FALSE | F15: FALSE | G15: =IF((F15+E15)*2>0,(F15+E15)*2,"") | J15: 3. und 4. Prüfungsfach durchgängig belegt | K15: {=_xlfn.LET( _xlpm.KursSp, INDEX($B$4:$G$34,0,MATCH("Kurs",$B$3:$G$3,0)), _xlpm.PFSp, INDEX($B$4:$G$34,0,MATCH("PF",$B$3:$G$3,0)), _xlpm.Halbjahr1,INDEX($B$4:$G$34,0,MATCH("Q1/2",$B$3:$G$3,0)), _xlpm.Halbjahr2,INDEX($B$4:$G$34,0,MATCH("Q3/4",$B$3:$G$3,0)), _xlpm.chk, SUMPRODUCT((_xlpm.PFSp="3. PF")*(_xlpm.Halbjahr1=TRUE)*(_xlpm.Halbjahr2=TRUE))>0, _xlpm.chkk, SUMPRODUCT((_xlpm.PFSp="4. PF")*(_xlpm.Halbjahr1=TRUE)*(_xlpm.Halbjahr2=TRUE))>0, AND(_xlpm.chk,_xlpm.chkk) )} -> FALSE
C16: Geografie bili | E16: FALSE | F16: FALSE | G16: =IF((F16+E16)*2>0,(F16+E16)*2,"") | J16: Referenzfach der 5. PK durchgängig belegt | K16: {=_xlfn.LET( _xlpm.PFSp, INDEX($B$4:$G$40,0,MATCH("PF",$B$3:$G$3,0)), _xlpm.Halbjahr1,INDEX($B$4:$G$40,0,MATCH("Q1/2",$B$3:$G$3,0)), _xlpm.Halbjahr2,INDEX($B$4:$G$40,0,MATCH("Q3/4",$B$3:$G$3,0)), SUMPRODUCT((_xlpm.PFSp="5. PK")*(_xlpm.Halbjahr1=TRUE)*(_xlpm.Halbjahr2=TRUE))>0 )} -> FALSE
C17: Philosophie | E17: FALSE | F17: FALSE | G17: =IF((F17+E17)*2>0,(F17+E17)*2,"") | J17: Aufgabenfeld 1
B18: 3. Aufgabenfeld | C18: Mathematik | E18: TRUE | F18: TRUE | G18: =IF((F18+E18)*2>0,(F18+E18)*2,"") -> 4 | J18: Deutsch vier Semester belegt | K18: {=_xlfn.LET( _xlpm.KursSp,INDEX($B$4:$G$40,0,MATCH("Kurs",$B$3:$G$3,0)), _xlpm.Halbjahr1,INDEX($B$4:$G$40,0,MATCH("Q1/2",$B$3:$G$3,0)), _xlpm.Halbjahr2,INDEX($B$4:$G$40,0,MATCH("Q3/4",$B$3:$G$3,0)), SUMPRODUCT((_xlpm.KursSp="Deutsch")*(_xlpm.Halbjahr1=TRUE)*(_xlpm.Halbjahr2=TRUE))>0 )} -> TRUE
C19: Physik | E19: FALSE | F19: FALSE | G19: =IF((F19+E19)*2>0,(F19+E19)*2,"") | J19: Fremdsprache vier Semester belegt | K19: {=_xlfn.LET( _xlpm.KursSp,INDEX($B$4:$G$34,0,MATCH("Kurs",$B$3:$G$3,0)), _xlpm.Halbjahr1,INDEX($B$4:$G$34,0,MATCH("Q1/2",$B$3:$G$3,0)), _xlpm.Halbjahr2,INDEX($B$4:$G$34,0,MATCH("Q3/4",$B$3:$G$3,0)), _xlpm.Kurs_FS,_xlfn._xlws.FILTER( INDEX('Angebotene Kurse'!$B$4:$G$29,0,MATCH("Kurs",'Angebotene Kurse'!$B$3:$G$3,0)), INDEX('Angebotene Kurse'!$B$4:$G$29,0,MATCH("Typ",'Angebotene Kurse'!$B$3:$G$3,0))="Fremdsprache" ), SUMPRODUCT((_xlpm.Halbjahr1=TRUE)*(_xlpm.Halbjahr2=TRUE)*ISNUMBER(MATCH(_xlpm.KursSp,_xlpm.Kurs_FS,0)))>0 )} -> FALSE
C20: Chemie | E20: FALSE | F20: FALSE | G20: =IF((F20+E20)*2>0,(F20+E20)*2,"") | J20: Ein künstlerisches Fach (Musik, Kunst, DS) zwei Semester belegt | K20: {=_xlfn.LET( _xlpm.KursSp, INDEX($B$4:$G$40,0,MATCH("Kurs",$B$3:$G$3,0)), _xlpm.Halbjahr1,INDEX($B$4:$G$40,0,MATCH("Q1/2",$B$3:$G$3,0)), _xlpm.Halbjahr2,INDEX($B$4:$G$40,0,MATCH("Q3/4",$B$3:$G$3,0)), _xlpm.Kurs_KUNST, _xlfn._xlws.FILTER( INDEX('Angebotene Kurse'!$B$4:$G$29,0,MATCH("Kurs",'Angebotene Kurse'!$B$3:$G$3,0)), INDEX('Angebotene Kurse'!$B$4:$G$29,0,MATCH("Typ",'Angebotene Kurse'!$B$3:$G$3,0))="Künstlerisch" ), SUMPRODUCT(((_xlpm.Halbjahr1=TRUE)+(_xlpm.Halbjahr2=TRUE)>0)*ISNUMBER(MATCH(_xlpm.KursSp,_xlpm.Kurs_KUNST,0)))>0 )} -> FALSE
C21: Biologie | E21: FALSE | F21: FALSE | G21: =IF((F21+E21)*2>0,(F21+E21)*2,"") | J21: Aufgabenfeld 2
C22: Informatik | E22: FALSE | F22: FALSE | G22: =IF((F22+E22)*2>0,(F22+E22)*2,"") | J22: Fach aus Aufgabenfeld 2 durchgängig belegt + zwei Semester eines weiteren Kurses | K22: {=_xlfn.LET( _xlpm.KursSp,INDEX($B$4:$G$40,0,MATCH("Kurs",$B$3:$G$3,0)), _xlpm.Halbjahr1,INDEX($B$4:$G$40,0,MATCH("Q1/2",$B$3:$G$3,0)), _xlpm.Halbjahr2,INDEX($B$4:$G$40,0,MATCH("Q3/4",$B$3:$G$3,0)), _xlpm.Z,ROW($B$4:$B$40), _xlpm.aufgabenfeld2,_xlfn.AGGREGATE(15,6,_xlpm.Z/($B$4:$B$40="2. Aufgabenfeld"),1), _xlpm.aufgabenfeld3,_xlfn.AGGREGATE(15,6,_xlpm.Z/($B$4:$B$40="3. Aufgabenfeld"),1), _xlpm.IN_BEREICH,(_xlpm.Z>=_xlpm.aufgabenfeld2)*(_xlpm.Z<_xlpm.aufgabenfeld3), _xlpm.count_durch,SUMPRODUCT(_xlpm.IN_BEREICH*(_xlpm.Halbjahr1=TRUE)*(_xlpm.Halbjahr2=TRUE)), _xlpm.count_any,SUMPRODUCT(_xlpm.IN_BEREICH*(((_xlpm.Halbjahr1=TRUE)+(_xlpm.Halbjahr2=TRUE))>0)), (_xlpm.count_durch>0)*(_xlpm.count_any>=2)>0 )} -> FALSE
B23: Sport | C23: Sport | E23: TRUE | F23: TRUE | G23: =IF((F23+E23)*2>0,(F23+E23)*2,"") -> 4 | J23: Ist Geschichte durchgängig belegt: Q3-Q4 Politik oder ein anderes Fach durchgängig | K23: {=_xlfn.LET( _xlpm.kopfzeilen,$B$3:$G$3, _xlpm.datenbereich,$B$4:$G$40, _xlpm.spalte_kurs,INDEX(_xlpm.datenbereich,0,MATCH("Kurs",_xlpm.kopfzeilen,0)), _xlpm.spalte_q12,INDEX(_xlpm.datenbereich,0,MATCH("Q1/2",_xlpm.kopfzeilen,0)), _xlpm.spalte_q34,INDEX(_xlpm.datenbereich,0,MATCH("Q3/4",_xlpm.kopfzeilen,0)), _xlpm.zeilenindex,ROW($B$4:$B$40), _xlpm.start_aufgabenfeld2,_xlfn.AGGREGATE(15,6,_xlpm.zeilenindex/($B$4:$B$40="2. Aufgabenfeld"),1), _xlpm.start_aufgabenfeld3,_xlfn.AGGREGATE(15,6,_xlpm.zeilenindex/($B$4:$B$40="3. Aufgabenfeld"),1), _xlpm.in_aufgabenfeld2,(_xlpm.zeilenindex>=_xlpm.start_aufgabenfeld2)*(_xlpm.zeilenindex<_xlpm.start_aufgabenfeld3), _xlpm.durchgehend_vec,(_xlpm.spalte_q12=TRUE)*(_xlpm.spalte_q34=TRUE), _xlpm.ist_geschichte,((_xlpm.spalte_kurs="Geschichte")+(_xlpm.spalte_kurs="Geschichte bili")>0), _xlpm.geschichte_durch,SUMPRODUCT(_xlpm.ist_geschichte*_xlpm.durchgehend_vec)>0, _xlpm.politik_q34,SUMPRODUCT((_xlpm.spalte_kurs="Politikwissenschaften")*(_xlpm.spalte_q34=TRUE))>0, _xlpm.anderes_af2_durch,SUMPRODUCT(_xlpm.in_aufgabenfeld2*(_xlpm.ist_geschichte=FALSE)*_xlpm.durchgehend_vec)>0, IF(_xlpm.geschichte_durch, OR(_xlpm.politik_q34, _xlpm.anderes_af2_durch), TRUE) )} -> TRUE
C24: Sport Theorie | E24: FALSE | F24: FALSE | G24: =IF((F24+E24)>0,(F24+E24)*2,"") | J24: Nicht Geschichte durchgängig belegt: Q3-Q4 Geschichte verpflichtend** | K24: {=_xlfn.LET( _xlpm.kopfzeilen,$B$3:$G$3, _xlpm.datenbereich,$B$4:$G$40, _xlpm.spalte_kurs,INDEX(_xlpm.datenbereich,0,MATCH("Kurs",_xlpm.kopfzeilen,0)), _xlpm.spalte_q12,INDEX(_xlpm.datenbereich,0,MATCH("Q1/2",_xlpm.kopfzeilen,0)), _xlpm.spalte_q34,INDEX(_xlpm.datenbereich,0,MATCH("Q3/4",_xlpm.kopfzeilen,0)), _xlpm.ist_geschichte,((_xlpm.spalte_kurs="Geschichte")+(_xlpm.spalte_kurs="Geschichte bili")>0), _xlpm.geschichte_durch,SUMPRODUCT(_xlpm.ist_geschichte*(_xlpm.spalte_q12=TRUE)*(_xlpm.spalte_q34=TRUE))>0, _xlpm.geschichte_q34,SUMPRODUCT(_xlpm.ist_geschichte*(_xlpm.spalte_q34=TRUE))>0, IF(NOT(_xlpm.geschichte_durch), _xlpm.geschichte_q34, TRUE) )} -> FALSE
C25: Skifahrt | E25: TRUE | G25: =IF((F25+E25)*2>0,(F25+E25),"") -> 1 | J25: Kurse nicht doppelt belegen (mit bilingualen Kursen) | K25: {=_xlfn.LET( _xlpm.kopfzeilen,Kurswahl!$B$3:$G$3, _xlpm.datenbereich,Kurswahl!$B$4:$G$40, _xlpm.spalte_kurs,INDEX(_xlpm.datenbereich,0,MATCH("Kurs",_xlpm.kopfzeilen,0)), _xlpm.spalte_q12,INDEX(_xlpm.datenbereich,0,MATCH("Q1/2",_xlpm.kopfzeilen,0)), _xlpm.spalte_q34,INDEX(_xlpm.datenbereich,0,MATCH("Q3/4",_xlpm.kopfzeilen,0)), _xlpm.basisname,IF(RIGHT(_xlpm.spalte_kurs,5)=" bili",LEFT(_xlpm.spalte_kurs,LEN(_xlpm.spalte_kurs)-5),_xlpm.spalte_kurs), _xlpm.paarmatrix,--(_xlpm.basisname=TRANSPOSE(_xlpm.basisname)), _xlpm.belegt,--(((_xlpm.spalte_q12=TRUE)+(_xlpm.spalte_q34=TRUE))>0), _xlpm.anzahl_belegt_pro_zeile,MMULT(_xlpm.paarmatrix,_xlpm.belegt), _xlpm.doppelt_gesamt,MAX(_xlpm.anzahl_belegt_pro_zeile*_xlpm.belegt)>1, NOT(_xlpm.doppelt_gesamt) )} -> TRUE
B26: Zusatzkurse | C26: Chor | E26: FALSE | F26: FALSE | G26: =IF((F26+E26)*2>0,(F26+E26)*2,"") | J26: Aufgabenfeld 3
C27: Orchester | E27: FALSE | F27: FALSE | G27: =IF((F27+E27)*2>0,(F27+E27)*2,"") | J27: Mathematik vier Semester belegt | K27: {=_xlfn.LET( _xlpm.KursSp,INDEX($B$4:$G$40,0,MATCH("Kurs",$B$3:$G$3,0)), _xlpm.Halbjahr1,INDEX($B$4:$G$40,0,MATCH("Q1/2",$B$3:$G$3,0)), _xlpm.Halbjahr2,INDEX($B$4:$G$40,0,MATCH("Q3/4",$B$3:$G$3,0)), SUMPRODUCT((_xlpm.KursSp="Mathematik")*(_xlpm.Halbjahr1=TRUE)*(_xlpm.Halbjahr2=TRUE))>0 )} -> TRUE
C28: Digitale Welten | E28: FALSE | F28: FALSE | G28: =IF((F28+E28)*2>0,(F28+E28)*2,"") | J28: Eine Naturwissenschaft durchgängig belegt | K28: {=_xlfn.LET( _xlpm.KursSp, INDEX($B$4:$G$40,0,MATCH("Kurs",$B$3:$G$3,0)), _xlpm.Halbjahr1,INDEX($B$4:$G$40,0,MATCH("Q1/2",$B$3:$G$3,0)), _xlpm.Halbjahr2,INDEX($B$4:$G$40,0,MATCH("Q3/4",$B$3:$G$3,0)), _xlpm.Kurs_NW, _xlfn._xlws.FILTER( INDEX('Angebotene Kurse'!$B$4:$G$29,0,MATCH("Kurs",'Angebotene Kurse'!$B$3:$G$3,0)), INDEX('Angebotene Kurse'!$B$4:$G$29,0,MATCH("Typ",'Angebotene Kurse'!$B$3:$G$3,0))="Naturwissenschaft" ), SUMPRODUCT((_xlpm.Halbjahr1=TRUE)*(_xlpm.Halbjahr2=TRUE)*ISNUMBER(MATCH(_xlpm.KursSp,_xlpm.Kurs_NW,0)))>0 )} -> FALSE
C29: Neuro | E29: FALSE | F29: FALSE | G29: =IF((F29+E29)*2>0,(F29+E29)*2,"") | J29: Bei Biologie: Belegung von mind. Q1/2 oder Q3/4 vom Fach Physik und/oder Chemie | K29: {=_xlfn.LET( _xlpm.KursSp,INDEX($B$4:$G$40,0,MATCH("Kurs",$B$3:$G$3,0)), _xlpm.Halbjahr1,INDEX($B$4:$G$40,0,MATCH("Q1/2",$B$3:$G$3,0)), _xlpm.Halbjahr2,INDEX($B$4:$G$40,0,MATCH("Q3/4",$B$3:$G$3,0)), _xlpm.bio_durch,SUMPRODUCT((_xlpm.KursSp="Biologie")*(_xlpm.Halbjahr1=TRUE)*(_xlpm.Halbjahr2=TRUE))>0, IF( _xlpm.bio_durch, SUMPRODUCT( ((_xlpm.KursSp="Physik")+(_xlpm.KursSp="Chemie")>0) * (((_xlpm.Halbjahr1=TRUE)+(_xlpm.Halbjahr2=TRUE))>0) )>0, TRUE ) )} -> TRUE
C30: STUB (ESB) | E30: FALSE | F30: FALSE | G30: =IF((F30+E30)*2>0,(F30+E30)*2,"") | J30: Vier Semester Sport-Praxis belegt | K30: {=_xlfn.LET( _xlpm.KursSp, INDEX($B$4:$G$40,0,MATCH("Kurs",$B$3:$G$3,0)), _xlpm.Halbjahr1,INDEX($B$4:$G$40,0,MATCH("Q1/2",$B$3:$G$3,0)), _xlpm.Halbjahr2,INDEX($B$4:$G$40,0,MATCH("Q3/4",$B$3:$G$3,0)), SUMPRODUCT((_xlpm.KursSp="Sport")*(_xlpm.Halbjahr1=TRUE)*(_xlpm.Halbjahr2=TRUE))>0 )} -> TRUE
C31: Sportmedizin | E31: FALSE | F31: FALSE | G31: =IF((F31+E31)*2>0,(F31+E31)*2,"") | J31: Schulinterne Regelungen
C32: CCC | E32: FALSE | F32: FALSE | G32: =IF((F32+E32)*2>0,(F32+E32)*2,"") | J32: Einhaltung der Leistungskurswahl mit dem schulinternen Angebot | K32: {=_xlfn.LET( _xlpm.kopfzeilen,$B$3:$G$3, _xlpm.datenbereich,$B$4:$G$40, _xlpm.spalte_kurs,INDEX(_xlpm.datenbereich,0,MATCH("Kurs",_xlpm.kopfzeilen,0)), _xlpm.spalte_pf,INDEX(_xlpm.datenbereich,0,MATCH("PF",_xlpm.kopfzeilen,0)), _xlpm.angebot_kopf,'Angebotene Kurse'!$B$3:$G$3, _xlpm.angebot_daten,'Angebotene Kurse'!$B$4:$G$1002, _xlpm.angebot_kurs,INDEX(_xlpm.angebot_daten,0,MATCH("Kurs",_xlpm.angebot_kopf,0)), _xlpm.angebot_lk, INDEX(_xlpm.angebot_daten,0,MATCH("LK?",_xlpm.angebot_kopf,0)), _xlpm.ist_pf_markiert,(_xlpm.spalte_pf="LF")+(_xlpm.spalte_pf="3. PF")+(_xlpm.spalte_pf="4. PF")+(_xlpm.spalte_pf="5. PK")>0, _xlpm.kurs_existiert,ISNUMBER(MATCH(_xlpm.spalte_kurs,_xlpm.angebot_kurs,0)), _xlpm.angebot_lk_map,IFERROR(_xlfn.XLOOKUP(_xlpm.spalte_kurs,_xlpm.angebot_kurs,_xlpm.angebot_lk,FALSE),FALSE), _xlpm.verletzung_existenz,SUMPRODUCT(_xlpm.ist_pf_markiert*(_xlpm.kurs_existiert=FALSE)), _xlpm.verletzung_lkflag,SUMPRODUCT((_xlpm.spalte_pf="LF")*(_xlpm.angebot_lk_map<>TRUE)), AND(_xlpm.verletzung_existenz=0, _xlpm.verletzung_lkflag=0) )} -> TRUE
C33: Debating | E33: FALSE | F33: FALSE | G33: =IF((F33+E33)*2>0,(F33+E33)*2,"") | J33: Einhaltung der Kurswahl mit dem schulinternen Angebot (Vgl. „Angebotene Kurse“) | K33: {=_xlfn.LET( _xlpm.kopfzeilen,$B$3:$G$3, _xlpm.datenbereich,$B$4:$G$40, _xlpm.spalte_kurs,INDEX(_xlpm.datenbereich,0,MATCH("Kurs",_xlpm.kopfzeilen,0)), _xlpm.spalte_q12,INDEX(_xlpm.datenbereich,0,MATCH("Q1/2",_xlpm.kopfzeilen,0)), _xlpm.spalte_q34,INDEX(_xlpm.datenbereich,0,MATCH("Q3/4",_xlpm.kopfzeilen,0)), _xlpm.angebot_kopf,'Angebotene Kurse'!$B$3:$G$3, _xlpm.angebot_daten,'Angebotene Kurse'!$B$4:$G$1002, _xlpm.angebot_kurs,INDEX(_xlpm.angebot_daten,0,MATCH("Kurs",_xlpm.angebot_kopf,0)), _xlpm.angebot_q12,INDEX(_xlpm.angebot_daten,0,MATCH("Q1/2",_xlpm.angebot_kopf,0)), _xlpm.angebot_q34,INDEX(_xlpm.angebot_daten,0,MATCH("Q3/4",_xlpm.angebot_kopf,0)), _xlpm.angebot_q12_map,IFERROR(_xlfn.XLOOKUP(_xlpm.spalte_kurs,_xlpm.angebot_kurs,_xlpm.angebot_q12,FALSE),FALSE), _xlpm.angebot_q34_map,IFERROR(_xlfn.XLOOKUP(_xlpm.spalte_kurs,_xlpm.angebot_kurs,_xlpm.angebot_q34,FALSE),FALSE), _xlpm.fehler_summe,SUMPRODUCT( (_xlpm.spalte_q12=TRUE)*(_xlpm.angebot_q12_map=FALSE) + (_xlpm.spalte_q34=TRUE)*(_xlpm.angebot_q34_map=FALSE) ), _xlpm.fehler_summe=0 )} -> TRUE
B34: ALLE | E34: =COUNTIFS(E4:E33,TRUE,C4:C33,"<>Skifahrt") -> 3 | F34: =COUNTIFS(F4:F33,TRUE,C4:C33,"<>Skifahrt") -> 3 | G34: =SUM(G4:G32) -> 13
J35: Kommentare ⇒
B36: Die Wahl ist für einige Fächer aufgrund des begrenzten schulischen Angebots eingeschränkt!

Sheet Notenrechner
B2: Notenrechner | O2: Zu erfüllende Regeln
C3: Kurs | D3: PF | E3: Q1 | G3: Q2 | I3: Q3 | K3: Q4
B4: {=_xlfn.LET( _xlpm.Daten, Kurswahl!B4:F32, _xlpm.AufgRoh, INDEX(_xlpm.Daten,,1), _xlpm.ZeilIdx, ROW(_xlpm.AufgRoh)-MIN(ROW(_xlpm.AufgRoh))+1, _xlpm.Kategorie, LOOKUP(_xlpm.ZeilIdx, IF(_xlpm.AufgRoh<>"", _xlpm.ZeilIdx), _xlpm.AufgRoh), _xlpm.Kurs, INDEX(_xlpm.Daten,,2), _xlpm.RechtsRoh, INDEX(_xlpm.Daten,,3), _xlpm.Rechts, IF(_xlpm.RechtsRoh="", "", _xlpm.RechtsRoh), _xlpm.Maske, ((INDEX(_xlpm.Daten,,4)+INDEX(_xlpm.Daten,,5))>0) * (_xlpm.Kurs<>"Skifahrt"), _xlpm.KatF, _xlfn._xlws.FILTER(_xlpm.Kategorie, _xlpm.Maske), _xlpm.KursF, _xlfn._xlws.FILTER(_xlpm.Kurs, _xlpm.Maske), _xlpm.RechtsF, _xlfn._xlws.FILTER(_xlpm.Rechts, _xlpm.Maske), _xlpm.n, ROWS(_xlpm.KatF), _xlpm.Pos, _xlfn.SEQUENCE(_xlpm.n), _xlpm.FirstFlag, (_xlpm.Pos=1) + (_xlpm.KatF<>INDEX(_xlpm.KatF, _xlpm.Pos-1)), _xlpm.Label, IF(_xlpm.FirstFlag, _xlpm.KatF, ""), _xlfn.HSTACK(_xlpm.Label, _xlpm.KursF, _xlpm.RechtsF) )} -> 1. Aufgabenfeld | C4: Deutsch | E4: 14 | F4: FALSE | G4: 11 | H4: TRUE | I4: 10 | J4: FALSE | L4: FALSE | O4: Genau 32 Kurse eingebracht (nicht zu viele auswählen!) | P4: {=_xlfn.LET( _xlpm.kursnamen,$C$4:$C$17, _xlpm.kurswahl_kopfzeilen,Kurswahl!$B$3:$G$3, _xlpm.kurswahl_zeilen,Kurswahl!$B$4:$G$100, _xlpm.kurswahl_spalte_kurs,Kurswahl!$C$4:$C$100, _xlpm.kurswahl_spalte_q12,INDEX(_xlpm.kurswahl_zeilen,0,MATCH("Q1/2",_xlpm.kurswahl_kopfzeilen,0)), _xlpm.kurswahl_spalte_q34,INDEX(_xlpm.kurswahl_zeilen,0,MATCH("Q3/4",_xlpm.kurswahl_kopfzeilen,0)), _xlpm.erlaubnis_q12,_xlfn.XLOOKUP(_xlpm.kursnamen,_xlpm.kurswahl_spalte_kurs,_xlpm.kurswahl_spalte_q12,FALSE)=TRUE, _xlpm.erlaubnis_q34,_xlfn.XLOOKUP(_xlpm.kursnamen,_xlpm.kurswahl_spalte_kurs,_xlpm.kurswahl_spalte_q34,FALSE)=TRUE, _xlpm.check_q1,$F$4:$F$17=TRUE, _xlpm.check_q2,$H$4:$H$17=TRUE, _xlpm.check_q3,$J$4:$J$17=TRUE, _xlpm.check_q4,$L$4:$L$17=TRUE, _xlpm.wertlinks_q1,NOT($E$4:$E$17=0), _xlpm.wertlinks_q2,NOT($G$4:$G$17=0), _xlpm.wertlinks_q3,NOT($I$4:$I$17=0), _xlpm.wertlinks_q4,NOT($K$4:$K$17=0), _xlpm.anzahl_regulaer,SUMPRODUCT( (_xlpm.check_q1*_xlpm.erlaubnis_q12*_xlpm.wertlinks_q1) + (_xlpm.check_q2*_xlpm.erlaubnis_q12*_xlpm.wertlinks_q2) + (_xlpm.check_q3*_xlpm.erlaubnis_q34*_xlpm.wertlinks_q3) + (_xlpm.check_q4*_xlpm.erlaubnis_q34*_xlpm.wertlinks_q4) ), _xlpm.skifahrt_kursname,$G$23, _xlpm.skifahrt_checkbox,$J$23=TRUE, _xlpm.skifahrt_wertlinks,NOT($I$23=0), _xlpm.skifahrt_q12,_xlfn.XLOOKUP(_xlpm.skifahrt_kursname,_xlpm.kurswahl_spalte_kurs,_xlpm.kurswahl_spalte_q12,FALSE)=TRUE, _xlpm.skifahrt_q34,_xlfn.XLOOKUP(_xlpm.skifahrt_kursname,_xlpm.kurswahl_spalte_kurs,_xlpm.kurswahl_spalte_q34,FALSE)=TRUE, _xlpm.skifahrt_erlaubt,OR(_xlpm.skifahrt_q12,_xlpm.skifahrt_q34), _xlpm.gesamt,_xlpm.anzahl_regulaer + N(_xlpm.skifahrt_checkbox*_xlpm.skifahrt_erlaubt*_xlpm.skifahrt_wertlinks), _xlpm.output, _xlfn.CONCAT(_xlfn.IFS(_xlpm.gesamt=32,TRUE,_xlpm.gesamt>32,"ZU VIELE",TRUE,FALSE), " (", _xlpm.gesamt, ")"), _xlpm.output )} -> FALSCH (2)
B5: 3. Aufgabenfeld | C5: Mathematik | E5: 13 | F5: TRUE | H5: FALSE | J5: FALSE | L5: FALSE | O5: Davon genau 8 Leistungskurse | P5: {=_xlfn.LET( _xlpm.kopfzeilen,$B$3:$L$3, _xlpm.datenbereich,$B$4:$L$17, _xlpm.spalte_pf,INDEX(_xlpm.datenbereich,0,MATCH("PF",_xlpm.kopfzeilen,0)), _xlpm.semester1,$F$4:$F$17, _xlpm.semester2,$H$4:$H$17, _xlpm.semester3,$J$4:$J$17, _xlpm.semester4,$L$4:$L$17, _xlpm.lk_mask,(_xlpm.spalte_pf="LF"), _xlpm.anzahl_lk,SUMPRODUCT( ((_xlpm.semester1=TRUE)+(_xlpm.semester2=TRUE)+(_xlpm.semester3=TRUE)+(_xlpm.semester4=TRUE)) * _xlpm.lk_mask ), _xlpm.anzahl_lk=8 )} -> FALSE
B6: Sport | C6: Sport | F6: FALSE | H6: FALSE | J6: FALSE | L6: FALSE | O6: Mind. 40 Kurse belegt (Alle Kurse eintragen, auch die nicht angekreuzt sind!) | P6: {=_xlfn.LET( _xlpm.kursnamen,$C$4:$C$17, _xlpm.punkteQ1,$E$4:$E$17, _xlpm.punkteQ2,$G$4:$G$17, _xlpm.punkteQ3,$I$4:$I$17, _xlpm.punkteQ4,$K$4:$K$17, _xlpm.kw_kopf,Kurswahl!$B$3:$G$3, _xlpm.kw_zeilen,Kurswahl!$B$4:$G$100, _xlpm.kw_kurs,Kurswahl!$C$4:$C$100, _xlpm.kw_q12,INDEX(_xlpm.kw_zeilen,0,MATCH("Q1/2",_xlpm.kw_kopf,0)), _xlpm.kw_q34,INDEX(_xlpm.kw_zeilen,0,MATCH("Q3/4",_xlpm.kw_kopf,0)), _xlpm.erlaubt_q12,_xlfn.XLOOKUP(_xlpm.kursnamen,_xlpm.kw_kurs,_xlpm.kw_q12,FALSE)=TRUE, _xlpm.erlaubt_q34,_xlfn.XLOOKUP(_xlpm.kursnamen,_xlpm.kw_kurs,_xlpm.kw_q34,FALSE)=TRUE, _xlpm.anzahl, SUMPRODUCT((_xlpm.punkteQ1>0)*_xlpm.erlaubt_q12)+ SUMPRODUCT((_xlpm.punkteQ2>0)*_xlpm.erlaubt_q12)+ SUMPRODUCT((_xlpm.punkteQ3>0)*_xlpm.erlaubt_q34)+ SUMPRODUCT((_xlpm.punkteQ4>0)*_xlpm.erlaubt_q34)+ N(($I$23>0) * OR( _xlfn.XLOOKUP($G$23,_xlpm.kw_kurs,_xlpm.kw_q12,FALSE)=TRUE, _xlfn.XLOOKUP($G$23,_xlpm.kw_kurs,_xlpm.kw_q34,FALSE)=TRUE )), CONCATENATE(IF(_xlpm.anzahl>=40,TRUE,FALSE)," (",_xlpm.anzahl,")") )} -> FALSCH (4)
F7: FALSE | H7: FALSE | J7: FALSE | L7: FALSE | O7: Alle 4 Sportkurse mehr als 0 Pkt | P7: {=IFERROR( _xlfn.LET( _xlpm.kopfzeilen,$B$3:$L$3, _xlpm.datenbereich,$B$4:$L$17, _xlpm.spalte_kurs,INDEX(_xlpm.datenbereich,0,MATCH("Kurs",_xlpm.kopfzeilen,0)), _xlpm.spalte,MATCH("Sport",_xlpm.spalte_kurs,0), _xlpm.semester1,INDEX(_xlpm.datenbereich,_xlpm.spalte,MATCH("Q1",_xlpm.kopfzeilen,0)), _xlpm.semester2,INDEX(_xlpm.datenbereich,_xlpm.spalte,MATCH("Q2",_xlpm.kopfzeilen,0)), _xlpm.semester3,INDEX(_xlpm.datenbereich,_xlpm.spalte,MATCH("Q3",_xlpm.kopfzeilen,0)), _xlpm.semester4,INDEX(_xlpm.datenbereich,_xlpm.spalte,MATCH("Q4",_xlpm.kopfzeilen,0)), AND(_xlpm.semester1>0,_xlpm.semester2>0,_xlpm.semester3>0,_xlpm.semester4>0) ), FALSE )} -> FALSE
F8: FALSE | H8: FALSE | J8: FALSE | L8: FALSE | O8: Punkte-Regelungen
F9: FALSE | H9: FALSE | J9: FALSE | L9: FALSE | O9: Mindestens 300 Punkte insgesamt | P9: =G26>=300 -> FALSE
F10: FALSE | H10: FALSE | J10: FALSE | L10: FALSE | O10: 80 Punkte in den LKs (2-fache Wertung), davon max. 2 Semester unter 5 Notenpunkten | P10: {=_xlfn.LET( _xlpm.kopfzeilen,$B$3:$L$3, _xlpm.datenbereich,$B$4:$L$17, _xlpm.spalte_kurs,INDEX(_xlpm.datenbereich,0,MATCH("Kurs",_xlpm.kopfzeilen,0)), _xlpm.spalte_pf,INDEX(_xlpm.datenbereich,0,MATCH("PF",_xlpm.kopfzeilen,0)), _xlpm.kurswahl_kopfzeilen,Kurswahl!$B$3:$G$3, _xlpm.kurswahl_zeilen,Kurswahl!$B$4:$G$100, _xlpm.kurswahl_spalte_kurs,Kurswahl!$C$4:$C$100, _xlpm.kurswahl_spalte_q12,INDEX(_xlpm.kurswahl_zeilen,0,MATCH("Q1/2",_xlpm.kurswahl_kopfzeilen,0)), _xlpm.kurswahl_spalte_q34,INDEX(_xlpm.kurswahl_zeilen,0,MATCH("Q3/4",_xlpm.kurswahl_kopfzeilen,0)), _xlpm.erlaubnis_q12,_xlfn.XLOOKUP(_xlpm.spalte_kurs,_xlpm.kurswahl_spalte_kurs,_xlpm.kurswahl_spalte_q12,FALSE)=TRUE, _xlpm.erlaubnis_q34,_xlfn.XLOOKUP(_xlpm.spalte_kurs,_xlpm.kurswahl_spalte_kurs,_xlpm.kurswahl_spalte_q34,FALSE)=TRUE, _xlpm.gueltig_q1,($F$4:$F$17=TRUE)*_xlpm.erlaubnis_q12*($E$4:$E$17<>0), _xlpm.gueltig_q2,($H$4:$H$17=TRUE)*_xlpm.erlaubnis_q12*($G$4:$G$17<>0), _xlpm.gueltig_q3,($J$4:$J$17=TRUE)*_xlpm.erlaubnis_q34*($I$4:$I$17<>0), _xlpm.gueltig_q4,($L$4:$L$17=TRUE)*_xlpm.erlaubnis_q34*($K$4:$K$17<>0), _xlpm.noten_q1,$E$4:$E$17, _xlpm.noten_q2,$G$4:$G$17, _xlpm.noten_q3,$I$4:$I$17, _xlpm.noten_q4,$K$4:$K$17, _xlpm.leistungsfach_kennzeichen,_xlpm.spalte_pf="LF", _xlpm.anzahl_leistungsfach_semester_mit_weniger_fuenf, SUMPRODUCT( _xlpm.leistungsfach_kennzeichen* ( _xlpm.gueltig_q1*(_xlpm.noten_q1<=5)+ _xlpm.gueltig_q2*(_xlpm.noten_q2<=5)+ _xlpm.gueltig_q3*(_xlpm.noten_q3<=5)+ _xlpm.gueltig_q4*(_xlpm.noten_q4<=5) ) ), AND($G$28>=80,_xlpm.anzahl_leistungsfach_semester_mit_weniger_fuenf<2) )} -> FALSE
F11: FALSE | H11: FALSE | J11: FALSE | L11: FALSE | O11: 120 Punkte in den GKs und 20 der 24 GKs jeweils mind. 5 Punkte (genug Kurse auswählen!) | P11: {=_xlfn.LET( _xlpm.kopfzeilen,$B$3:$L$3, _xlpm.datenbereich,$B$4:$L$17, _xlpm.spalte_kurs,INDEX(_xlpm.datenbereich,0,MATCH("Kurs",_xlpm.kopfzeilen,0)), _xlpm.spalte_pf,INDEX(_xlpm.datenbereich,0,MATCH("PF",_xlpm.kopfzeilen,0)), _xlpm.kurswahl_kopfzeilen,Kurswahl!$B$3:$G$3, _xlpm.kurswahl_zeilen,Kurswahl!$B$4:$G$100, _xlpm.kurswahl_spalte_kurs,Kurswahl!$C$4:$C$100, _xlpm.kurswahl_spalte_q12,INDEX(_xlpm.kurswahl_zeilen,0,MATCH("Q1/2",_xlpm.kurswahl_kopfzeilen,0)), _xlpm.kurswahl_spalte_q34,INDEX(_xlpm.kurswahl_zeilen,0,MATCH("Q3/4",_xlpm.kurswahl_kopfzeilen,0)), _xlpm.erlaubnis_q12,_xlfn.XLOOKUP(_xlpm.spalte_kurs,_xlpm.kurswahl_spalte_kurs,_xlpm.kurswahl_spalte_q12,FALSE)=TRUE, _xlpm.erlaubnis_q34,_xlfn.XLOOKUP(_xlpm.spalte_kurs,_xlpm.kurswahl_spalte_kurs,_xlpm.kurswahl_spalte_q34,FALSE)=TRUE, _xlpm.gueltig_q1,($F$4:$F$17=TRUE)*_xlpm.erlaubnis_q12*($E$4:$E$17<>0), _xlpm.gueltig_q2,($H$4:$H$17=TRUE)*_xlpm.erlaubnis_q12*($G$4:$G$17<>0), _xlpm.gueltig_q3,($J$4:$J$17=TRUE)*_xlpm.erlaubnis_q34*($I$4:$I$17<>0), _xlpm.gueltig_q4,($L$4:$L$17=TRUE)*_xlpm.erlaubnis_q34*($K$4:$K$17<>0), _xlpm.noten_q1,$E$4:$E$17, _xlpm.noten_q2,$G$4:$G$17, _xlpm.noten_q3,$I$4:$I$17, _xlpm.noten_q4,$K$4:$K$17, _xlpm.grundkurs_kennzeichen,_xlpm.spalte_pf<>"LF", _xlpm.anzahl_grundkurs_semester_mit_mindestens_fuenf, SUMPRODUCT( _xlpm.grundkurs_kennzeichen* ( _xlpm.gueltig_q1*(_xlpm.noten_q1>=5)+ _xlpm.gueltig_q2*(_xlpm.noten_q2>=5)+ _xlpm.gueltig_q3*(_xlpm.noten_q3>=5)+ _xlpm.gueltig_q4*(_xlpm.noten_q4>=5) ) ), _xlpm.skifahrt_kursname,$G$23, _xlpm.skifahrt_kurswahl_kopfzeilen,Kurswahl!$B$3:$G$3, _xlpm.skifahrt_kurswahl_zeilen,Kurswahl!$B$4:$G$100, _xlpm.skifahrt_kurswahl_spalte_kurs,Kurswahl!$C$4:$C$100, _xlpm.skifahrt_kurswahl_spalte_q12,INDEX(_xlpm.skifahrt_kurswahl_zeilen,0,MATCH("Q1/2",_xlpm.skifahrt_kurswahl_kopfzeilen,0)), _xlpm.skifahrt_kurswahl_spalte_q34,INDEX(_xlpm.skifahrt_kurswahl_zeilen,0,MATCH("Q3/4",_xlpm.skifahrt_kurswahl_kopfzeilen,0)), _xlpm.skifahrt_erlaubnis_q12,_xlfn.XLOOKUP(_xlpm.skifahrt_kursname,_xlpm.skifahrt_kurswahl_spalte_kurs,_xlpm.skifahrt_kurswahl_spalte_q12,FALSE)=TRUE, _xlpm.skifahrt_erlaubnis_q34,_xlfn.XLOOKUP(_xlpm.skifahrt_kursname,_xlpm.skifahrt_kurswahl_spalte_kurs,_xlpm.skifahrt_kurswahl_spalte_q34,FALSE)=TRUE, _xlpm.skifahrt_erlaubt,OR(_xlpm.skifahrt_erlaubnis_q12,_xlpm.skifahrt_erlaubnis_q34), _xlpm.skifahrt_mindestens_fuenf,(J23=TRUE)*(I23<>0)*(I23>=5)*_xlpm.skifahrt_erlaubt, _xlpm.gesamt_semester_mit_mindestens_fuenf, _xlpm.anzahl_grundkurs_semester_mit_mindestens_fuenf+N(_xlpm.skifahrt_mindestens_fuenf), AND($G$29>=120,_xlpm.gesamt_semester_mit_mindestens_fuenf>=20) )} -> FALSE
F12: FALSE | H12: FALSE | J12: TRUE | L12: FALSE | O12: Kein Kurs mit 0 Punkten eingebracht (auch kein LK) im Kursblock | P12: {=_xlfn.LET( _xlpm.kopfzeilen,$B$3:$L$3, _xlpm.datenbereich,$B$4:$L$17, _xlpm.spalte_kurs,INDEX(_xlpm.datenbereich,0,MATCH("Kurs",_xlpm.kopfzeilen,0)), _xlpm.kurswahl_kopfzeilen,Kurswahl!$B$3:$G$3, _xlpm.kurswahl_zeilen,Kurswahl!$B$4:$G$100, _xlpm.kurswahl_spalte_kurs,Kurswahl!$C$4:$C$100, _xlpm.kurswahl_spalte_q12,INDEX(_xlpm.kurswahl_zeilen,0,MATCH("Q1/2",_xlpm.kurswahl_kopfzeilen,0)), _xlpm.kurswahl_spalte_q34,INDEX(_xlpm.kurswahl_zeilen,0,MATCH("Q3/4",_xlpm.kurswahl_kopfzeilen,0)), _xlpm.erlaubnis_q12,_xlfn.XLOOKUP(_xlpm.spalte_kurs,_xlpm.kurswahl_spalte_kurs,_xlpm.kurswahl_spalte_q12,FALSE)=TRUE, _xlpm.erlaubnis_q34,_xlfn.XLOOKUP(_xlpm.spalte_kurs,_xlpm.kurswahl_spalte_kurs,_xlpm.kurswahl_spalte_q34,FALSE)=TRUE, _xlpm.eingebracht_q1,($F$4:$F$17=TRUE)*_xlpm.erlaubnis_q12, _xlpm.eingebracht_q2,($H$4:$H$17=TRUE)*_xlpm.erlaubnis_q12, _xlpm.eingebracht_q3,($J$4:$J$17=TRUE)*_xlpm.erlaubnis_q34, _xlpm.eingebracht_q4,($L$4:$L$17=TRUE)*_xlpm.erlaubnis_q34, _xlpm.noten_q1,$E$4:$E$17, _xlpm.noten_q2,$G$4:$G$17, _xlpm.noten_q3,$I$4:$I$17, _xlpm.noten_q4,$K$4:$K$17, _xlpm.anzahl_null_qualifikationsphase, SUMPRODUCT( _xlpm.eingebracht_q1*(_xlpm.noten_q1=0)+ _xlpm.eingebracht_q2*(_xlpm.noten_q2=0)+ _xlpm.eingebracht_q3*(_xlpm.noten_q3=0)+ _xlpm.eingebracht_q4*(_xlpm.noten_q4=0) ), _xlpm.skifahrt_kursname,$G$23, _xlpm.skifahrt_kurswahl_kopfzeilen,Kurswahl!$B$3:$G$3, _xlpm.skifahrt_kurswahl_zeilen,Kurswahl!$B$4:$G$100, _xlpm.skifahrt_kurswahl_spalte_kurs,Kurswahl!$C$4:$C$100, _xlpm.skifahrt_kurswahl_spalte_q12,INDEX(_xlpm.skifahrt_kurswahl_zeilen,0,MATCH("Q1/2",_xlpm.skifahrt_kurswahl_kopfzeilen,0)), _xlpm.skifahrt_kurswahl_spalte_q34,INDEX(_xlpm.skifahrt_kurswahl_zeilen,0,MATCH("Q3/4",_xlpm.skifahrt_kurswahl_kopfzeilen,0)), _xlpm.skifahrt_erlaubnis_q12,_xlfn.XLOOKUP(_xlpm.skifahrt_kursname,_xlpm.skifahrt_kurswahl_spalte_kurs,_xlpm.skifahrt_kurswahl_spalte_q12,FALSE)=TRUE, _xlpm.skifahrt_erlaubnis_q34,_xlfn.XLOOKUP(_xlpm.skifahrt_kursname,_xlpm.skifahrt_kurswahl_spalte_kurs,_xlpm.skifahrt_kurswahl_spalte_q34,FALSE)=TRUE, _xlpm.skifahrt_erlaubt,OR(_xlpm.skifahrt_erlaubnis_q12,_xlpm.skifahrt_erlaubnis_q34), _xlpm.anzahl_null_skifahrt,N((J23=TRUE)*_xlpm.skifahrt_erlaubt*(I23=0)), _xlpm.gesamt_null,_xlpm.anzahl_null_qualifikationsphase+_xlpm.anzahl_null_skifahrt, _xlpm.gesamt_null=0 )} -> TRUE
F13: FALSE | H13: FALSE | J13: FALSE | L13: FALSE | O13: Mind. 100 Punkte in den Prüfungen (4-fache Wertung) und in zwei Prüfungsfächern (darunter mind. 1 LK) jeweils mind. 20 Notenpunkte (4-fach) | P13: {=_xlfn.LET( _xlpm.ausgefuellt,COUNT($E$19:$E$23)=5, _xlpm.pf1_ok,IF(AND($C$30=TRUE,NOT($I$19="")),$I$19>=20,$E$19>=5), _xlpm.pf2_ok,IF(AND($C$30=TRUE,NOT($I$20="")),$I$20>=20,$E$20>=5), _xlpm.pf3_ok,IF(AND($C$30=TRUE,NOT($I$21="")),$I$21>=20,$E$21>=5), _xlpm.pf4_ok,$E$22>=5, _xlpm.anz_pf_ge5,N(_xlpm.pf1_ok)+N(_xlpm.pf2_ok)+N(_xlpm.pf3_ok)+N(_xlpm.pf4_ok), _xlpm.anz_lk_ge5,N(($D$19="LF")*_xlpm.pf1_ok)+N(($D$20="LF")*_xlpm.pf2_ok)+N(($D$21="LF")*_xlpm.pf3_ok)+N(($D$22="LF")*_xlpm.pf4_ok), IF(NOT(_xlpm.ausgefuellt),"AUSFÜLLEN",AND($G$30>=100,_xlpm.anz_pf_ge5>=2,_xlpm.anz_lk_ge5>=1)) )} -> AUSFÜLLEN
F14: FALSE | H14: FALSE | J14: FALSE | L14: FALSE
F15: FALSE | H15: FALSE | J15: FALSE | L15: FALSE | O15: Prüfungsfächer
F16: FALSE | H16: FALSE | J16: FALSE | L16: FALSE | O16: 3. und 4. Prüfungsfach durchgängig eingebracht (Außnahme Sport, s.u.) | P16: {=_xlfn.LET( _xlpm.kopfzeilen,$B$3:$L$3, _xlpm.datenbereich,$B$4:$L$17, _xlpm.spalte_kurs,INDEX(_xlpm.datenbereich,0,MATCH("Kurs",_xlpm.kopfzeilen,0)), _xlpm.spalte_pf,INDEX(_xlpm.datenbereich,0,MATCH("PF",_xlpm.kopfzeilen,0)), _xlpm.semester1,$F$4:$F$17, _xlpm.semester2,$H$4:$H$17, _xlpm.semester3,$J$4:$J$17, _xlpm.semester4,$L$4:$L$17, _xlpm.chk_drittes,SUMPRODUCT((_xlpm.spalte_pf="3. PF")*(_xlpm.semester1=TRUE)*(_xlpm.semester2=TRUE)*(_xlpm.semester3=TRUE)*(_xlpm.semester4=TRUE))>0, _xlpm.chk_viertes,SUMPRODUCT((_xlpm.spalte_pf="4. PF")*(_xlpm.semester1=TRUE)*(_xlpm.semester2=TRUE)*(_xlpm.semester3=TRUE)*(_xlpm.semester4=TRUE))>0, _xlpm.sport_als_3oder4,SUMPRODUCT(((_xlpm.spalte_kurs="Sport")+(_xlpm.spalte_kurs="Sport Theorie")>0)*(((_xlpm.spalte_pf="3. PF")+(_xlpm.spalte_pf="4. PF"))>0))>0, OR(AND(_xlpm.chk_drittes,_xlpm.chk_viertes), _xlpm.sport_als_3oder4) )} -> FALSE
F17: FALSE | H17: FALSE | J17: FALSE | L17: FALSE | O17: Ist Sport PF: 1 Kurs Sport Theorie und 3 Kurse Praxis einbringen* + noch möglich: Noch max. ein Kurs Sport Theorie oder Praxis | P17: {=_xlfn.LET( _xlpm.kopfzeilen,$B$3:$L$3, _xlpm.datenbereich,$B$4:$L$17, _xlpm.spalte_kurs,INDEX(_xlpm.datenbereich,0,MATCH("Kurs",_xlpm.kopfzeilen,0)), _xlpm.spalte_pf,INDEX(_xlpm.datenbereich,0,MATCH("PF",_xlpm.kopfzeilen,0)), _xlpm.kursnamen_fuer_abgleich,_xlpm.spalte_kurs, _xlpm.kurswahl_kopfzeilen,Kurswahl!$B$3:$G$3, _xlpm.kurswahl_zeilen,Kurswahl!$B$4:$G$100, _xlpm.kurswahl_spalte_kurs,Kurswahl!$C$4:$C$100, _xlpm.kurswahl_spalte_q12,INDEX(_xlpm.kurswahl_zeilen,0,MATCH("Q1/2",_xlpm.kurswahl_kopfzeilen,0)), _xlpm.kurswahl_spalte_q34,INDEX(_xlpm.kurswahl_zeilen,0,MATCH("Q3/4",_xlpm.kurswahl_kopfzeilen,0)), _xlpm.erlaubnis_q12,_xlfn.XLOOKUP(_xlpm.kursnamen_fuer_abgleich,_xlpm.kurswahl_spalte_kurs,_xlpm.kurswahl_spalte_q12,FALSE)=TRUE, _xlpm.erlaubnis_q34,_xlfn.XLOOKUP(_xlpm.kursnamen_fuer_abgleich,_xlpm.kurswahl_spalte_kurs,_xlpm.kurswahl_spalte_q34,FALSE)=TRUE, _xlpm.check_q1,$F$4:$F$17=TRUE, _xlpm.check_q2,$H$4:$H$17=TRUE, _xlpm.check_q3,$J$4:$J$17=TRUE, _xlpm.check_q4,$L$4:$L$17=TRUE, _xlpm.wertlinks_q1,$E$4:$E$17<>0, _xlpm.wertlinks_q2,$G$4:$G$17<>0, _xlpm.wertlinks_q3,$I$4:$I$17<>0, _xlpm.wertlinks_q4,$K$4:$K$17<>0, _xlpm.beitrag_q1,_xlpm.check_q1*_xlpm.erlaubnis_q12*_xlpm.wertlinks_q1, _xlpm.beitrag_q2,_xlpm.check_q2*_xlpm.erlaubnis_q12*_xlpm.wertlinks_q2, _xlpm.beitrag_q3,_xlpm.check_q3*_xlpm.erlaubnis_q34*_xlpm.wertlinks_q3, _xlpm.beitrag_q4,_xlpm.check_q4*_xlpm.erlaubnis_q34*_xlpm.wertlinks_q4, _xlpm.sport_ist_pf,SUMPRODUCT(((_xlpm.spalte_pf="LF")+(_xlpm.spalte_pf="3. PF")+(_xlpm.spalte_pf="4. PF")>0)*(((_xlpm.spalte_kurs="Sport")+(_xlpm.spalte_kurs="Sport Theorie"))>0))>0, _xlpm.theorie_eingebracht,SUMPRODUCT((_xlpm.spalte_kurs="Sport Theorie")*(_xlpm.beitrag_q1+_xlpm.beitrag_q2+_xlpm.beitrag_q3+_xlpm.beitrag_q4)), _xlpm.praxis_eingebracht,SUMPRODUCT((_xlpm.spalte_kurs="Sport")*(_xlpm.beitrag_q1+_xlpm.beitrag_q2+_xlpm.beitrag_q3+_xlpm.beitrag_q4)), _xlpm.skifahrt_kursname,$G$23, _xlpm.skifahrt_checkbox,$J$23=TRUE, _xlpm.skifahrt_wertlinks,$I$23<>0, _xlpm.skifahrt_q12,_xlfn.XLOOKUP(_xlpm.skifahrt_kursname,_xlpm.kurswahl_spalte_kurs,_xlpm.kurswahl_spalte_q12,FALSE)=TRUE, _xlpm.skifahrt_q34,_xlfn.XLOOKUP(_xlpm.skifahrt_kursname,_xlpm.kurswahl_spalte_kurs,_xlpm.kurswahl_spalte_q34,FALSE)=TRUE, _xlpm.skifahrt_erlaubt,OR(_xlpm.skifahrt_q12,_xlpm.skifahrt_q34), _xlpm.praxis_inkl_skifahrt,_xlpm.praxis_eingebracht+N(_xlpm.skifahrt_checkbox*_xlpm.skifahrt_wertlinks*_xlpm.skifahrt_erlaubt), _xlpm.gesamt_sport,_xlpm.theorie_eingebracht+_xlpm.praxis_inkl_skifahrt, IF(_xlpm.sport_ist_pf,AND(_xlpm.theorie_eingebracht>=1,_xlpm.praxis_inkl_skifahrt>=3,_xlpm.gesamt_sport<=5),TRUE) )} -> TRUE
C18: Kurs | D18: PF | E18: Note | G18: NP-Note
B19: Abiturprüfungen | C19: {=_xlfn.LET( _xlpm.Tabelle, Kurswahl!B4:G34, _xlpm.Koepfe, Kurswahl!B3:G3, _xlpm.idxKurs, MATCH("Kurs", _xlpm.Koepfe, 0), _xlpm.idxPF, MATCH("PF", _xlpm.Koepfe, 0), _xlpm.KursSp, INDEX(_xlpm.Tabelle,, _xlpm.idxKurs), _xlpm.PF_Roh, INDEX(_xlpm.Tabelle,, _xlpm.idxPF), _xlpm.PF, SUBSTITUTE(CLEAN(TRIM(_xlpm.PF_Roh)), CHAR(160), ""), _xlpm.MaskePF, _xlpm.PF<>"", _xlpm.KursF, _xlfn._xlws.FILTER(_xlpm.KursSp, _xlpm.MaskePF), _xlpm.PFF, _xlfn._xlws.FILTER(_xlpm.PF, _xlpm.MaskePF), _xlpm.RowIdx, _xlfn._xlws.FILTER(ROW(_xlpm.KursSp), _xlpm.MaskePF), _xlpm.ok, AND( SUMPRODUCT(--(LEFT(_xlpm.PF,2)="LF"))=2, SUMPRODUCT(--(LEFT(_xlpm.PF,5)="3. PF"))=1, SUMPRODUCT(--(LEFT(_xlpm.PF,5)="4. PF"))=1, SUMPRODUCT(--(LEFT(_xlpm.PF,5)="5. PK"))=1 ), _xlpm.KursF_adj, IF((_xlpm.KursF="Sport")*(((LEFT(_xlpm.PFF,5)="3. PF")+(LEFT(_xlpm.PFF,5)="4. PF"))>0),"Sport*",_xlpm.KursF), _xlpm.SortKey, _xlfn.IFS( LEFT(_xlpm.PFF,2)="LF", 1, LEFT(_xlpm.PFF,5)="3. PF", 2, LEFT(_xlpm.PFF,5)="4. PF", 3, LEFT(_xlpm.PFF,5)="5. PK", 4 ), _xlpm.Ausgabe, _xlfn.SORTBY(_xlfn.HSTACK(_xlpm.KursF_adj, _xlpm.PFF), _xlpm.SortKey, 1, _xlpm.RowIdx, 1), IF(_xlpm.ok, _xlpm.Ausgabe, "") )} | F19: & | O19: Letztes Semester des Referenzfaches der 5. PK eingebracht (Außnahme Sport, s.u.) | P19: {=_xlfn.LET( _xlpm.kopfzeilen,$B$3:$L$3, _xlpm.datenbereich,$B$4:$L$17, _xlpm.spalte_kurs,INDEX(_xlpm.datenbereich,0,MATCH("Kurs",_xlpm.kopfzeilen,0)), _xlpm.spalte_pf,INDEX(_xlpm.datenbereich,0,MATCH("PF",_xlpm.kopfzeilen,0)), _xlpm.semester4,$L$4:$L$17, _xlpm.q4_ref_5pk,SUMPRODUCT((_xlpm.spalte_pf="5. PK")*(_xlpm.semester4=TRUE))>0, _xlpm.sport_als_5pk,SUMPRODUCT(((_xlpm.spalte_kurs="Sport")+(_xlpm.spalte_kurs="Sport Theorie")>0)*(_xlpm.spalte_pf="5. PK"))>0, OR(_xlpm.q4_ref_5pk, _xlpm.sport_als_5pk) )} -> FALSE
F20: & | O20: Ist Sport 5. PK: Letzter Kurs Sport Theorie einzubringen* & 4 weitere Sportkurse möglich (davon noch max. 1x Sport Theorie) | P20: {=_xlfn.LET( _xlpm.kopfzeilen,$B$3:$L$3, _xlpm.datenbereich,$B$4:$L$17, _xlpm.spalte_kurs,INDEX(_xlpm.datenbereich,0,MATCH("Kurs",_xlpm.kopfzeilen,0)), _xlpm.spalte_pf,INDEX(_xlpm.datenbereich,0,MATCH("PF",_xlpm.kopfzeilen,0)), _xlpm.kursnamen_fuer_abgleich,_xlpm.spalte_kurs, _xlpm.kurswahl_kopfzeilen,Kurswahl!$B$3:$G$3, _xlpm.kurswahl_zeilen,Kurswahl!$B$4:$G$100, _xlpm.kurswahl_spalte_kurs,Kurswahl!$C$4:$C$100, _xlpm.kurswahl_spalte_q12,INDEX(_xlpm.kurswahl_zeilen,0,MATCH("Q1/2",_xlpm.kurswahl_kopfzeilen,0)), _xlpm.kurswahl_spalte_q34,INDEX(_xlpm.kurswahl_zeilen,0,MATCH("Q3/4",_xlpm.kurswahl_kopfzeilen,0)), _xlpm.erlaubnis_q12,_xlfn.XLOOKUP(_xlpm.kursnamen_fuer_abgleich,_xlpm.kurswahl_spalte_kurs,_xlpm.kurswahl_spalte_q12,FALSE)=TRUE, _xlpm.erlaubnis_q34,_xlfn.XLOOKUP(_xlpm.kursnamen_fuer_abgleich,_xlpm.kurswahl_spalte_kurs,_xlpm.kurswahl_spalte_q34,FALSE)=TRUE, _xlpm.check_q1,$F$4:$F$17=TRUE, _xlpm.check_q2,$H$4:$H$17=TRUE, _xlpm.check_q3,$J$4:$J$17=TRUE, _xlpm.check_q4,$L$4:$L$17=TRUE, _xlpm.wertlinks_q1,$E$4:$E$17<>0, _xlpm.wertlinks_q2,$G$4:$G$17<>0, _xlpm.wertlinks_q3,$I$4:$I$17<>0, _xlpm.wertlinks_q4,$K$4:$K$17<>0, _xlpm.beitrag_q1,_xlpm.check_q1*_xlpm.erlaubnis_q12*_xlpm.wertlinks_q1, _xlpm.beitrag_q2,_xlpm.check_q2*_xlpm.erlaubnis_q12*_xlpm.wertlinks_q2, _xlpm.beitrag_q3,_xlpm.check_q3*_xlpm.erlaubnis_q34*_xlpm.wertlinks_q3, _xlpm.beitrag_q4,_xlpm.check_q4*_xlpm.erlaubnis_q34*_xlpm.wertlinks_q4, _xlpm.sport_ist_pk5,SUMPRODUCT((((_xlpm.spalte_kurs="Sport")+(_xlpm.spalte_kurs="Sport Theorie"))>0)*(_xlpm.spalte_pf="5. PK"))>0, _xlpm.theorie_q4_muss,SUMPRODUCT((_xlpm.spalte_kurs="Sport Theorie")*_xlpm.beitrag_q4)>0, _xlpm.theorie_gesamt,SUMPRODUCT((_xlpm.spalte_kurs="Sport Theorie")*(_xlpm.beitrag_q1+_xlpm.beitrag_q2+_xlpm.beitrag_q3+_xlpm.beitrag_q4)), _xlpm.praxis_gesamt,SUMPRODUCT((_xlpm.spalte_kurs="Sport")*(_xlpm.beitrag_q1+_xlpm.beitrag_q2+_xlpm.beitrag_q3+_xlpm.beitrag_q4)), _xlpm.skifahrt_kursname,$G$23, _xlpm.skifahrt_checkbox,$J$23=TRUE, _xlpm.skifahrt_wertlinks,$I$23<>0, _xlpm.skifahrt_q12,_xlfn.XLOOKUP(_xlpm.skifahrt_kursname,_xlpm.kurswahl_spalte_kurs,_xlpm.kurswahl_spalte_q12,FALSE)=TRUE, _xlpm.skifahrt_q34,_xlfn.XLOOKUP(_xlpm.skifahrt_kursname,_xlpm.kurswahl_spalte_kurs,_xlpm.kurswahl_spalte_q34,FALSE)=TRUE, _xlpm.skifahrt_erlaubt,OR(_xlpm.skifahrt_q12,_xlpm.skifahrt_q34), _xlpm.praxis_gesamt_inkl,_xlpm.praxis_gesamt+N(_xlpm.skifahrt_checkbox*_xlpm.skifahrt_wertlinks*_xlpm.skifahrt_erlaubt), _xlpm.gesamt_sport,_xlpm.theorie_gesamt+_xlpm.praxis_gesamt_inkl, IF(_xlpm.sport_ist_pk5,AND(_xlpm.theorie_q4_muss,_xlpm.gesamt_sport<=5,_xlpm.theorie_gesamt<=2),TRUE) )} -> TRUE
F21: &
G22: Sonderkurs Skifahrt | O22: Abiprüfungen: Maximal zwei Nachprüfungen in den schriftlichen PFs | P22: =COUNTBLANK(G19:G21)>0 -> TRUE
G23: Skifahrt | J23: FALSE | O23: Aufgabenfeld 1
O24: Deutsch 4 Semester eingebracht | P24: {=_xlfn.LET( _xlpm.kopfzeilen,$B$3:$L$3, _xlpm.datenbereich,$B$4:$L$17, _xlpm.spalte_kurs,INDEX(_xlpm.datenbereich,0,MATCH("Kurs",_xlpm.kopfzeilen,0)), _xlpm.semester1,$F$4:$F$17, _xlpm.semester2,$H$4:$H$17, _xlpm.semester3,$J$4:$J$17, _xlpm.semester4,$L$4:$L$17, SUMPRODUCT((_xlpm.spalte_kurs="Deutsch")*(_xlpm.semester1=TRUE)*(_xlpm.semester2=TRUE)*(_xlpm.semester3=TRUE)*(_xlpm.semester4=TRUE))>0 )} -> FALSE
B25: Abiturnote | O25: Fremdsprache 4 Semester eingebracht | P25: {=_xlfn.LET( _xlpm.kopfzeilen,$B$3:$L$3, _xlpm.datenbereich,$B$4:$L$17, _xlpm.spalte_kurs,INDEX(_xlpm.datenbereich,0,MATCH("Kurs",_xlpm.kopfzeilen,0)), _xlpm.kurswahl_kopfzeilen,Kurswahl!$B$3:$G$3, _xlpm.kurswahl_zeilen,Kurswahl!$B$4:$G$100, _xlpm.kurswahl_spalte_kurs,Kurswahl!$C$4:$C$100, _xlpm.kurswahl_spalte_q12,INDEX(_xlpm.kurswahl_zeilen,0,MATCH("Q1/2",_xlpm.kurswahl_kopfzeilen,0)), _xlpm.kurswahl_spalte_q34,INDEX(_xlpm.kurswahl_zeilen,0,MATCH("Q3/4",_xlpm.kurswahl_kopfzeilen,0)), _xlpm.erlaubnis_q12,_xlfn.XLOOKUP(_xlpm.spalte_kurs,_xlpm.kurswahl_spalte_kurs,_xlpm.kurswahl_spalte_q12,FALSE)=TRUE, _xlpm.erlaubnis_q34,_xlfn.XLOOKUP(_xlpm.spalte_kurs,_xlpm.kurswahl_spalte_kurs,_xlpm.kurswahl_spalte_q34,FALSE)=TRUE, _xlpm.gueltig_q1,($F$4:$F$17=TRUE)*_xlpm.erlaubnis_q12*($E$4:$E$17<>0), _xlpm.gueltig_q2,($H$4:$H$17=TRUE)*_xlpm.erlaubnis_q12*($G$4:$G$17<>0), _xlpm.gueltig_q3,($J$4:$J$17=TRUE)*_xlpm.erlaubnis_q34*($I$4:$I$17<>0), _xlpm.gueltig_q4,($L$4:$L$17=TRUE)*_xlpm.erlaubnis_q34*($K$4:$K$17<>0), _xlpm.kurse_kopf,'Angebotene Kurse'!$B$3:$G$3, _xlpm.kurse_daten,'Angebotene Kurse'!$B$4:$G$1002, _xlpm.fs_kurse,_xlfn._xlws.FILTER(INDEX(_xlpm.kurse_daten,0,MATCH("Kurs",_xlpm.kurse_kopf,0)),INDEX(_xlpm.kurse_daten,0,MATCH("Typ",_xlpm.kurse_kopf,0))="Fremdsprache"), SUMPRODUCT(ISNUMBER(MATCH(_xlpm.spalte_kurs,_xlpm.fs_kurse,0))*(_xlpm.gueltig_q1*_xlpm.gueltig_q2*_xlpm.gueltig_q3*_xlpm.gueltig_q4))>0 )} -> FALSE
B26: Avg Punkte | C26: {=IFERROR( G26 / _xlfn.LET( _xlpm.kopfzeilen,$B$3:$L$3, _xlpm.datenbereich,$B$4:$L$17, _xlpm.spalte_kurs,INDEX(_xlpm.datenbereich,0,MATCH("Kurs",_xlpm.kopfzeilen,0)), _xlpm.kurswahl_kopfzeilen,Kurswahl!$B$3:$G$3, _xlpm.kurswahl_zeilen,Kurswahl!$B$4:$G$100, _xlpm.kurswahl_spalte_kurs,Kurswahl!$C$4:$C$100, _xlpm.kurswahl_spalte_q12,INDEX(_xlpm.kurswahl_zeilen,0,MATCH("Q1/2",_xlpm.kurswahl_kopfzeilen,0)), _xlpm.kurswahl_spalte_q34,INDEX(_xlpm.kurswahl_zeilen,0,MATCH("Q3/4",_xlpm.kurswahl_kopfzeilen,0)), _xlpm.erlaubnis_q12,_xlfn.XLOOKUP(_xlpm.spalte_kurs,_xlpm.kurswahl_spalte_kurs,_xlpm.kurswahl_spalte_q12,FALSE)=TRUE, _xlpm.erlaubnis_q34,_xlfn.XLOOKUP(_xlpm.spalte_kurs,_xlpm.kurswahl_spalte_kurs,_xlpm.kurswahl_spalte_q34,FALSE)=TRUE, _xlpm.gueltig_q1,($F$4:$F$17=TRUE)*_xlpm.erlaubnis_q12*($E$4:$E$17<>0), _xlpm.gueltig_q2,($H$4:$H$17=TRUE)*_xlpm.erlaubnis_q12*($G$4:$G$17<>0), _xlpm.gueltig_q3,($J$4:$J$17=TRUE)*_xlpm.erlaubnis_q34*($I$4:$I$17<>0), _xlpm.gueltig_q4,($L$4:$L$17=TRUE)*_xlpm.erlaubnis_q34*($K$4:$K$17<>0), _xlpm.gewicht_lk,(1+($D$4:$D$17="LF")), _xlpm.anzahl_semester,SUMPRODUCT( (_xlpm.gueltig_q1+_xlpm.gueltig_q2+_xlpm.gueltig_q3+_xlpm.gueltig_q4) * _xlpm.gewicht_lk ), _xlpm.skifahrt_kursname,$G$23, _xlpm.skifahrt_checkbox,$J$23=TRUE, _xlpm.skifahrt_wertlinks,$I$23<>0, _xlpm.skifahrt_q12,_xlfn.XLOOKUP(_xlpm.skifahrt_kursname,_xlpm.kurswahl_spalte_kurs,_xlpm.kurswahl_spalte_q12,FALSE)=TRUE, _xlpm.skifahrt_q34,_xlfn.XLOOKUP(_xlpm.skifahrt_kursname,_xlpm.kurswahl_spalte_kurs,_xlpm.kurswahl_spalte_q34,FALSE)=TRUE, _xlpm.skifahrt_erlaubt,OR(_xlpm.skifahrt_q12,_xlpm.skifahrt_q34), _xlpm.anzahl_semester + N(_xlpm.skifahrt_checkbox*_xlpm.skifahrt_wertlinks*_xlpm.skifahrt_erlaubt) + COUNTA(E19:E23)*4 ),0)} -> 12 | D26: Punkteanzahl | G26: {=$G$30+ _xlfn.LET( _xlpm.kopfzeilen,$B$3:$L$3, _xlpm.datenbereich,$B$4:$L$17, _xlpm.spalte_kurs,INDEX(_xlpm.datenbereich,0,MATCH("Kurs",_xlpm.kopfzeilen,0)), _xlpm.kurswahl_kopfzeilen,Kurswahl!$B$3:$G$3, _xlpm.kurswahl_zeilen,Kurswahl!$B$4:$G$100, _xlpm.kurswahl_spalte_kurs,Kurswahl!$C$4:$C$100, _xlpm.kurswahl_spalte_q12,INDEX(_xlpm.kurswahl_zeilen,0,MATCH("Q1/2",_xlpm.kurswahl_kopfzeilen,0)), _xlpm.kurswahl_spalte_q34,INDEX(_xlpm.kurswahl_zeilen,0,MATCH("Q3/4",_xlpm.kurswahl_kopfzeilen,0)), _xlpm.erlaubnis_q12,_xlfn.XLOOKUP(_xlpm.spalte_kurs,_xlpm.kurswahl_spalte_kurs,_xlpm.kurswahl_spalte_q12,FALSE)=TRUE, _xlpm.erlaubnis_q34,_xlfn.XLOOKUP(_xlpm.spalte_kurs,_xlpm.kurswahl_spalte_kurs,_xlpm.kurswahl_spalte_q34,FALSE)=TRUE, _xlpm.gueltig_q1,($F$4:$F$17=TRUE)*_xlpm.erlaubnis_q12*($E$4:$E$17<>0), _xlpm.gueltig_q2,($H$4:$H$17=TRUE)*_xlpm.erlaubnis_q12*($G$4:$G$17<>0), _xlpm.gueltig_q3,($J$4:$J$17=TRUE)*_xlpm.erlaubnis_q34*($I$4:$I$17<>0), _xlpm.gueltig_q4,($L$4:$L$17=TRUE)*_xlpm.erlaubnis_q34*($K$4:$K$17<>0), _xlpm.gewicht_lk,(1+($D$4:$D$17="LF")), _xlpm.summe_regel,SUMPRODUCT( ($E$4:$E$17*_xlpm.gueltig_q1 + $G$4:$G$17*_xlpm.gueltig_q2 + $I$4:$I$17*_xlpm.gueltig_q3 + $K$4:$K$17*_xlpm.gueltig_q4) * _xlpm.gewicht_lk ), _xlpm.skifahrt_kursname,$G$23, _xlpm.skifahrt_checkbox,$J$23=TRUE, _xlpm.skifahrt_wertlinks,$I$23<>0, _xlpm.skifahrt_q12,_xlfn.XLOOKUP(_xlpm.skifahrt_kursname,_xlpm.kurswahl_spalte_kurs,_xlpm.kurswahl_spalte_q12,FALSE)=TRUE, _xlpm.skifahrt_q34,_xlfn.XLOOKUP(_xlpm.skifahrt_kursname,_xlpm.kurswahl_spalte_kurs,_xlpm.kurswahl_spalte_q34,FALSE)=TRUE, _xlpm.skifahrt_erlaubt,OR(_xlpm.skifahrt_q12,_xlpm.skifahrt_q34), _xlpm.skifahrt_punkte,$I$23*N(_xlpm.skifahrt_checkbox*_xlpm.skifahrt_wertlinks*_xlpm.skifahrt_erlaubt), _xlpm.summe_regel+_xlpm.skifahrt_punkte )} -> 24 | O26: Ein künstlerisches Fach (Musik, DS, Kunst) 2 Semester eingebracht | P26: {=_xlfn.LET( _xlpm.kopfzeilen,$B$3:$L$3, _xlpm.datenbereich,$B$4:$L$17, _xlpm.spalte_kurs,INDEX(_xlpm.datenbereich,0,MATCH("Kurs",_xlpm.kopfzeilen,0)), _xlpm.kurswahl_kopfzeilen,Kurswahl!$B$3:$G$3, _xlpm.kurswahl_zeilen,Kurswahl!$B$4:$G$100, _xlpm.kurswahl_spalte_kurs,Kurswahl!$C$4:$C$100, _xlpm.kurswahl_spalte_q12,INDEX(_xlpm.kurswahl_zeilen,0,MATCH("Q1/2",_xlpm.kurswahl_kopfzeilen,0)), _xlpm.kurswahl_spalte_q34,INDEX(_xlpm.kurswahl_zeilen,0,MATCH("Q3/4",_xlpm.kurswahl_kopfzeilen,0)), _xlpm.erlaubnis_q12,_xlfn.XLOOKUP(_xlpm.spalte_kurs,_xlpm.kurswahl_spalte_kurs,_xlpm.kurswahl_spalte_q12,FALSE)=TRUE, _xlpm.erlaubnis_q34,_xlfn.XLOOKUP(_xlpm.spalte_kurs,_xlpm.kurswahl_spalte_kurs,_xlpm.kurswahl_spalte_q34,FALSE)=TRUE, _xlpm.gueltig_q1,($F$4:$F$17=TRUE)*_xlpm.erlaubnis_q12*($E$4:$E$17<>0), _xlpm.gueltig_q2,($G$4:$H$17=TRUE)*_xlpm.erlaubnis_q12*($G$4:$G$17<>0), _xlpm.gueltig_q3,($J$4:$J$17=TRUE)*_xlpm.erlaubnis_q34*($H$4:$I$17<>0), _xlpm.gueltig_q4,($L$4:$L$17=TRUE)*_xlpm.erlaubnis_q34*($K$4:$K$17<>0), _xlpm.anzahl_gueltig_pro_zeile,_xlpm.gueltig_q1+_xlpm.gueltig_q2+_xlpm.gueltig_q3+_xlpm.gueltig_q4, _xlpm.kurse_kopf,'Angebotene Kurse'!$B$3:$G$3, _xlpm.kurse_daten,'Angebotene Kurse'!$B$4:$G$1002, _xlpm.kunst_kurse,_xlfn._xlws.FILTER(INDEX(_xlpm.kurse_daten,0,MATCH("Kurs",_xlpm.kurse_kopf,0)),INDEX(_xlpm.kurse_daten,0,MATCH("Typ",_xlpm.kurse_kopf,0))="Künstlerisch"), SUMPRODUCT(ISNUMBER(MATCH(_xlpm.spalte_kurs,_xlpm.kunst_kurse,0))*(_xlpm.anzahl_gueltig_pro_zeile>=2))>0 )} -> FALSE
B27: Abiturnote | C27: =TRUNC((17/3-C26/3)*10, 0)/10 -> 1.6 | D27: Kursblock | G27: =G26-G30 -> 24 | O27: Aufgabenfeld 2
D28: Leistungskurse | G28: {=SUMPRODUCT( (D4:D17="LF") * ( E4:E17 +G4:G17 +I4:I17 +K4:K17 ) )*2} -> 0 | O28: Ein Fach durchgängig belegen und einbringen | P28: {=_xlfn.LET( _xlpm.notenrechner_Kopfzeile,$B$3:$L$3, _xlpm.notenrechner_Datenbereich,$B$4:$L$17, _xlpm.notenrechner_KursnamenSpalte,INDEX(_xlpm.notenrechner_Datenbereich,0,MATCH("Kurs",_xlpm.notenrechner_Kopfzeile,0)), _xlpm.kurswahl_Kopfzeile,Kurswahl!$B$3:$G$3, _xlpm.kurswahl_Datenbereich,Kurswahl!$B$4:$G$100, _xlpm.kurswahl_KursnamenSpalte,Kurswahl!$C$4:$C$100, _xlpm.kurswahl_BelegungSpalte_Q12,INDEX(_xlpm.kurswahl_Datenbereich,0,MATCH("Q1/2",_xlpm.kurswahl_Kopfzeile,0)), _xlpm.kurswahl_BelegungSpalte_Q34,INDEX(_xlpm.kurswahl_Datenbereich,0,MATCH("Q3/4",_xlpm.kurswahl_Kopfzeile,0)), _xlpm.notenrechner_BelegungErlaubt_Q12,_xlfn.XLOOKUP(_xlpm.notenrechner_KursnamenSpalte,_xlpm.kurswahl_KursnamenSpalte,_xlpm.kurswahl_BelegungSpalte_Q12,FALSE)=TRUE, _xlpm.notenrechner_BelegungErlaubt_Q34,_xlfn.XLOOKUP(_xlpm.notenrechner_KursnamenSpalte,_xlpm.kurswahl_KursnamenSpalte,_xlpm.kurswahl_BelegungSpalte_Q34,FALSE)=TRUE, _xlpm.notenrechner_Einbringung_Halbjahr_Eins,($F$4:$F$17=TRUE)*_xlpm.notenrechner_BelegungErlaubt_Q12*($E$4:$E$17<>0), _xlpm.notenrechner_Einbringung_Halbjahr_Zwei,($H$4:$H$17=TRUE)*_xlpm.notenrechner_BelegungErlaubt_Q12*($G$4:$G$17<>0), _xlpm.notenrechner_Einbringung_Halbjahr_Drei,($J$4:$J$17=TRUE)*_xlpm.notenrechner_BelegungErlaubt_Q34*($I$4:$I$17<>0), _xlpm.notenrechner_Einbringung_Halbjahr_Vier,($L$4:$L$17=TRUE)*_xlpm.notenrechner_BelegungErlaubt_Q34*($K$4:$K$17<>0), _xlpm.notenrechner_DurchgaengigEingebracht,_xlpm.notenrechner_Einbringung_Halbjahr_Eins*_xlpm.notenrechner_Einbringung_Halbjahr_Zwei*_xlpm.notenrechner_Einbringung_Halbjahr_Drei*_xlpm.notenrechner_Einbringung_Halbjahr_Vier, _xlpm.notenrechner_ZeilenIndex,ROW($B$4:$B$17), _xlpm.notenrechner_Start_ZweitesAufgabenfeld,_xlfn.AGGREGATE(15,6,_xlpm.notenrechner_ZeilenIndex/($B$4:$B$17="2. Aufgabenfeld"),1), _xlpm.notenrechner_Start_DrittesAufgabenfeld,IFERROR(_xlfn.AGGREGATE(15,6,_xlpm.notenrechner_ZeilenIndex/($B$4:$B$17="3. Aufgabenfeld"),1),ROW($B$17)+1), _xlpm.notenrechner_ImZweitenAufgabenfeld,(_xlpm.notenrechner_ZeilenIndex>=_xlpm.notenrechner_Start_ZweitesAufgabenfeld)*(_xlpm.notenrechner_ZeilenIndex<_xlpm.notenrechner_Start_DrittesAufgabenfeld), _xlpm.output,SUMPRODUCT(_xlpm.notenrechner_ImZweitenAufgabenfeld*_xlpm.notenrechner_DurchgaengigEingebracht)>0, IFERROR(_xlpm.output,FALSE) )} -> FALSE
